[2022-04-14 06:37:27,177] {taskinstance.py:876} INFO - Dependencies all met for <TaskInstance: user_processing.creating_table 2022-04-13T00:00:00+00:00 [queued]>
[2022-04-14 06:37:27,241] {taskinstance.py:876} INFO - Dependencies all met for <TaskInstance: user_processing.creating_table 2022-04-13T00:00:00+00:00 [queued]>
[2022-04-14 06:37:27,242] {taskinstance.py:1067} INFO - 
--------------------------------------------------------------------------------
[2022-04-14 06:37:27,242] {taskinstance.py:1068} INFO - Starting attempt 1 of 1
[2022-04-14 06:37:27,242] {taskinstance.py:1069} INFO - 
--------------------------------------------------------------------------------
[2022-04-14 06:37:27,289] {taskinstance.py:1087} INFO - Executing <Task(SqliteOperator): creating_table> on 2022-04-13T00:00:00+00:00
[2022-04-14 06:37:27,307] {standard_task_runner.py:52} INFO - Started process 4593 to run task
[2022-04-14 06:37:27,314] {standard_task_runner.py:76} INFO - Running: ['airflow', 'tasks', 'run', 'user_processing', 'creating_table', '2022-04-13T00:00:00+00:00', '--job-id', '54', '--pool', 'default_pool', '--raw', '--subdir', 'DAGS_FOLDER/user_processing.py', '--cfg-path', '/tmp/tmpp34wope4', '--error-file', '/tmp/tmpb5b2p3nx']
[2022-04-14 06:37:27,322] {standard_task_runner.py:77} INFO - Job 54: Subtask creating_table
[2022-04-14 06:37:27,570] {logging_mixin.py:104} INFO - Running <TaskInstance: user_processing.creating_table 2022-04-13T00:00:00+00:00 [running]> on host airflowvm
[2022-04-14 06:37:37,776] {taskinstance.py:1280} INFO - Exporting the following env vars:
AIRFLOW_CTX_DAG_OWNER=airflow
AIRFLOW_CTX_DAG_ID=user_processing
AIRFLOW_CTX_TASK_ID=creating_table
AIRFLOW_CTX_EXECUTION_DATE=2022-04-13T00:00:00+00:00
AIRFLOW_CTX_DAG_RUN_ID=scheduled__2022-04-13T00:00:00+00:00
[2022-04-14 06:37:37,777] {sqlite.py:63} INFO - Executing: 
                    create table IF NOT EXISTS statedata(
                      
                        state_id text integer not null,
                        state_name text not null
                        
                    );
                
[2022-04-14 06:37:37,830] {taskinstance.py:1481} ERROR - Task failed with exception
Traceback (most recent call last):
  File "/home/airflow/sandbox/lib/python3.8/site-packages/airflow/models/taskinstance.py", line 1137, in _run_raw_task
    self._prepare_and_execute_task_with_callbacks(context, task)
  File "/home/airflow/sandbox/lib/python3.8/site-packages/airflow/models/taskinstance.py", line 1311, in _prepare_and_execute_task_with_callbacks
    result = self._execute_task(context, task_copy)
  File "/home/airflow/sandbox/lib/python3.8/site-packages/airflow/models/taskinstance.py", line 1341, in _execute_task
    result = task_copy.execute(context=context)
  File "/home/airflow/sandbox/lib/python3.8/site-packages/airflow/providers/sqlite/operators/sqlite.py", line 65, in execute
    hook.run(self.sql, parameters=self.parameters)
  File "/home/airflow/sandbox/lib/python3.8/site-packages/airflow/hooks/dbapi.py", line 177, in run
    with closing(self.get_conn()) as conn:
  File "/home/airflow/sandbox/lib/python3.8/site-packages/airflow/providers/sqlite/hooks/sqlite.py", line 35, in get_conn
    airflow_conn = self.get_connection(conn_id)
  File "/home/airflow/sandbox/lib/python3.8/site-packages/airflow/hooks/base.py", line 67, in get_connection
    conn = Connection.get_connection_from_secrets(conn_id)
  File "/home/airflow/sandbox/lib/python3.8/site-packages/airflow/models/connection.py", line 379, in get_connection_from_secrets
    raise AirflowNotFoundException(f"The conn_id `{conn_id}` isn't defined")
airflow.exceptions.AirflowNotFoundException: The conn_id `db_sqlite` isn't defined
[2022-04-14 06:37:37,855] {taskinstance.py:1524} INFO - Marking task as FAILED. dag_id=user_processing, task_id=creating_table, execution_date=20220413T000000, start_date=20220414T063727, end_date=20220414T063737
[2022-04-14 06:37:37,977] {local_task_job.py:151} INFO - Task exited with return code 1
